Workbook

Sheet Görev Takibi
A1: Faz | B1: No | C1: Görev | D1: Gün | E1: Tarih | F1: Efor (sa) | G1: Bağımlılık | H1: Kapattığı bulgu | I1: Yapıldı mı? | J1: Not
A2: Faz 0 — Temizlik ve Zemin | B2: 0.1 | C2: .gitignore'u genişlet: myvenv/, .venv/, *.db, __pycache__/, .env, .idea/, .vscode/, .pytest_cache/ | D2: 1 | E2: 18.08.2026 Sal | F2: 0.33 | G2: — | H2: B-03 | I2: ✓
A3: Faz 0 — Temizlik ve Zemin | B3: 0.2 | C3: git rm -r --cached myvenv dev.db v1_db.db ile takipten çıkar ve commit'le | D3: 1 | E3: 18.08.2026 Sal | F3: 0.33 | G3: 0.1 | H3: B-03 | I3: ✓ | J3: Kontrol edilemedi: git deposu bu klasörde görünmüyor. 'git ls-files myvenv dev.db v1_db.db' boş dönmeli.
A4: Faz 0 — Temizlik ve Zemin | B4: 0.3 | C4: requirements.txt düzelt: aiosqltite→aiosqlite, pydantic-settings + greenlet ekle, databases çıkar, sürümleri pinle | D4: 1 | E4: 18.08.2026 Sal | F4: 0.75 | G4: — | H4: B-02 | I4: ✓ | J4: requirements.txt düzgün ve pinli. Eksik: requirements-dev.txt henüz yok (test bağımlılıkları gelince ayır).
A5: Faz 0 — Temizlik ve Zemin | B5: 0.4 | C5: Settings'i genişlet: ENV, CORS_ORIGINS, JWT_SECRET, JWT_ALGORITHM, ACCESS_TOKEN_EXPIRE_MINUTES | D5: 1 | E5: 18.08.2026 Sal | F5: 0.75 | G5: 0.3 | H5: B-15 | I5: ✓
A6: Faz 0 — Temizlik ve Zemin | B6: 0.5 | C6: .env.example yaz (gerçek değer yok, sadece anahtar isimleri) | D6: 1 | E6: 18.08.2026 Sal | F6: 0.33 | G6: 0.4 | H6: B-18 | I6: ✓
A7: Faz 0 — Temizlik ve Zemin | B7: 0.6 | C7: core/security.py'yi temizle: debug print ve ölü yorum bloğunu sil | D7: 1 | E7: 18.08.2026 Sal | F7: 0.17 | G7: — | H7: B-01 | I7: ✓
A8: Faz 0 — Temizlik ve Zemin | B8: 0.7 | C8: README.md'yi UTF-8 olarak yeniden yaz; models/readme.md ve schemas/readme.md'yi güncelle | D8: 1 | E8: 18.08.2026 Sal | F8: 0.75 | G8: — | H8: B-17, B-20 | I8: ✓
A9: Faz 0 — Temizlik ve Zemin | B9: 0.8 | C9: bug_report.json'ı docs/ altına arşivle veya sil | D9: 1 | E9: 18.08.2026 Sal | F9: 0.17 | G9: — | H9: — | I9: ✓
A10: Faz 0 — Temizlik ve Zemin | B10: 0.K | C10: KONTROL: temiz klonda pip install + uvicorn app.main:app çalışıyor | D10: 1 | E10: 18.08.2026 Sal | F10: 0.25 | G10: 0.3 | H10: — | I10: ✓
A11: Faz 1 — Router, Şema, Repository | B11: 1.1 | C11: api/v1/router.py + api/router.py doldur; main.py tek include_router yapsın; wildcard import'u kaldır | D11: 2 | E11: 19.08.2026 Çar | F11: 0.75 | G11: Faz 0 | H11: B-13, B-19 | I11: ✓
A12: Faz 1 — Router, Şema, Repository | B12: 1.2 | C12: Şemaları ayır: ProjectCreate (id yok), ProjectUpdate (hepsi Optional), ProjectRead (id+tarihler) | D12: 2 | E12: 19.08.2026 Çar | F12: 1.5 | G12: 1.1 | H12: B-04, B-12 | I12: ✓
A13: Faz 1 — Router, Şema, Repository | B13: 1.3 | C13: response_model'leri ProjectRead yap; SQLModel table model'i API yüzeyinden çek | D13: 2 | E13: 19.08.2026 Çar | F13: 0.5 | G13: 1.2 | H13: B-05 | I13: ✓ | J13: ⚠ Kısmen: GET route'ları ProjectRead dönüyor; POST, PATCH ve PUT /slug route'larında response_model yok → tablo modeli (snake_case) dönüyor.
A14: Faz 1 — Router, Şema, Repository | B14: 1.4 | C14: Alan adlarını snake_case'e çevir + alias_generator=to_camel ile JSON'da camelCase koru | D14: 2 | E14: 19.08.2026 Çar | F14: 1.5 | G14: 1.2 | H14: B-16 | I14: ✓
A15: Faz 1 — Router, Şema, Repository | B15: 1.5 | C15: BaseModel'den name'i çıkar; id + created_at + updated_at bırak; Project'e kendi name'ini ekle | D15: 3 | E15: 20.08.2026 Per | F15: 0.75 | G15: 1.2 | H15: B-10, B-11 | I15: ✓
A16: Faz 1 — Router, Şema, Repository | B16: 1.6 | C16: get_by_slug'ı ProjectRepository'ye taşı; update'i exclude_unset=True ile partial update yap | D16: 3 | E16: 20.08.2026 Per | F16: 1 | G16: 1.5 | H16: B-07, B-09 | I16: ✓ | J16: ⚠ Kısmen: PATCH exclude_unset ile çalışıyor. get_by_slug ise hâlâ BaseRepository içinde (ProjectRepository'de override edilmiş).
A17: Faz 1 — Router, Şema, Repository | B17: 1.7 | C17: PUT/PATCH/DELETE endpoint'leri + Page[T] sayfalama şeması (items, total, page, size) | D17: 3 | E17: 20.08.2026 Per | F17: 1.5 | G17: 1.6 | H17: B-07, B-21 | I17: ✓ | J17: Kısmen: PUT/PATCH/DELETE route'ları var. Page[T] sayfalama şeması yok (get_all düz liste dönüyor).
A18: Faz 1 — Router, Şema, Repository | B18: 1.8 | C18: db_dependency'ye try/except/rollback ekle | D18: 3 | E18: 20.08.2026 Per | F18: 0.33 | G18: — | H18: B-08 | I18: ✓ | J18: Yapılmadı: db_dependency'de try/except/rollback yok.
A19: Faz 1 — Router, Şema, Repository | B19: 1.K | C19: KONTROL: /docs'ta 5 project endpoint'i; POST id istemiyor; PATCH tek alan güncelliyor | D19: 3 | E19: 20.08.2026 Per | F19: 0.25 | G19: 1.7 | H19: — | I19: ✓ | J19: Doğrulandı: POST id istemiyor, PATCH tek alan güncelliyor, projects için PUT/PATCH/DELETE route'ları /docs'ta var.
A20: Faz 2 — Test Altyapısı | B20: 2.1 | C20: pytest + pytest-asyncio + httpx; conftest.py: in-memory async engine, AsyncClient fixture, dependency override | D20: 3 | E20: 20.08.2026 Per | F20: 2 | G20: Faz 1 | H20: B-14 | J20: Yapılmadı: tests/ klasörü yok.
A21: Faz 2 — Test Altyapısı | B21: 2.2 | C21: test_projects.py: create/list/get/update/delete + 404 + 422 + sayfalama testleri | D21: 3 | E21: 20.08.2026 Per | F21: 2 | G21: 2.1 | H21: B-14
A22: Faz 2 — Test Altyapısı | B22: 2.K | C22: KONTROL: pytest yeşil, en az 10 test geçiyor | D22: 3 | E22: 20.08.2026 Per | F22: 0.25 | G22: 2.2 | H22: —
A23: Faz 3 — Alembic + PostgreSQL | B23: 3.1 | C23: alembic init -t async alembic; env.py'yi SQLModel metadata + settings.DATABASE_URL ile bağla | D23: 4 | E23: 21.08.2026 Cum | F23: 1.5 | G23: Faz 1 | H23: B-06 | J23: Yapılmadı: alembic/ klasörü yok; db.py hâlâ create_all kullanıyor.
A24: Faz 3 — Alembic + PostgreSQL | B24: 3.2 | C24: İlk migration'ı üret; init_db()/create_all çağrısını lifespan'den kaldır | D24: 4 | E24: 21.08.2026 Cum | F24: 1 | G24: 3.1 | H24: B-06
A25: Faz 3 — Alembic + PostgreSQL | B25: 3.3 | C25: docker-compose.yml'e postgres:17-alpine ekle; asyncpg bağımlılığı; DATABASE_URL env'den | D25: 4 | E25: 21.08.2026 Cum | F25: 1.5 | G25: 3.2 | H25: —
A26: Faz 3 — Alembic + PostgreSQL | B26: 3.4 | C26: Migration + testleri Postgres'e karşı çalıştır; JSON→JSONB davranışını doğrula | D26: 4 | E26: 21.08.2026 Cum | F26: 1 | G26: 3.3 | H26: —
A27: Faz 3 — Alembic + PostgreSQL | B27: 3.K | C27: KONTROL: boş Postgres'te alembic upgrade head şemayı kuruyor; pytest iki DB'de de yeşil | D27: 4 | E27: 21.08.2026 Cum | F27: 0.25 | G27: 3.4 | H27: —
A28: Faz 4 — Blog (Post) Modülü | B28: 4.1 | C28: Post modeli: title, slug (unique+index), summary, content (Text), cover_image_url, tags, status, published_at, reading_time | D28: 5 | E28: 22.08.2026 Cmt | F28: 2 | G28: Faz 3 | H28: —
A29: Faz 4 — Blog (Post) Modülü | B29: 4.2 | C29: PostCreate/Update/Read şemaları; python-slugify ile Türkçe karakter → ASCII slug | D29: 5 | E29: 22.08.2026 Cmt | F29: 1.5 | G29: 4.1 | H29: —
A30: Faz 4 — Blog (Post) Modülü | B30: 4.3 | C30: PostRepository: slug ile getir, sadece published listele, tag filtresi, published_at DESC sırala | D30: 5 | E30: 22.08.2026 Cmt | F30: 1.5 | G30: 4.2 | H30: —
A31: Faz 4 — Blog (Post) Modülü | B31: 4.4 | C31: /api/v1/posts endpoint'leri: public list (published), public get-by-slug, admin CRUD | D31: 6 | E31: 23.08.2026 Paz | F31: 2 | G31: 4.3 | H31: —
A32: Faz 4 — Blog (Post) Modülü | B32: 4.5 | C32: Alembic migration + test_posts.py (draft'ın public listede görünmediğini de test et) | D32: 6 | E32: 23.08.2026 Paz | F32: 1 | G32: 4.4 | H32: —
A33: Faz 4 — Blog (Post) Modülü | B33: 4.K | C33: KARAR: markdown backend'de HTML'e çevrilmeyecek — ham dönülüp frontend render edecek | D33: 6 | E33: 23.08.2026 Paz | F33: 0.25 | G33: 4.1 | H33: —
A34: Faz 5 — Admin Auth (JWT) | B34: 5.1 | C34: User modeli: email (unique), hashed_password, is_active, is_admin + migration | D34: 7 | E34: 24.08.2026 Pzt | F34: 1 | G34: Faz 3 | H34: B-01 | J34: Taslak var (models/user.py) ama table=True değil, hashed_password/is_active/is_admin yok.
A35: Faz 5 — Admin Auth (JWT) | B35: 5.2 | C35: core/security.py: pwdlib[argon2] ile hash/verify + PyJWT ile access token üret/çöz | D35: 7 | E35: 24.08.2026 Pzt | F35: 2 | G35: 5.1 | H35: B-01 | J35: core/security.py şu an boş (0 bayt).
A36: Faz 5 — Admin Auth (JWT) | B36: 5.3 | C36: POST /api/v1/auth/login (OAuth2PasswordRequestForm) → access token; GET /auth/me | D36: 7 | E36: 24.08.2026 Pzt | F36: 1.5 | G36: 5.2 | H36: B-01
A37: Faz 5 — Admin Auth (JWT) | B37: 5.4 | C37: dependencies.py → get_current_admin: OAuth2PasswordBearer + token doğrulama + 401/403 | D37: 8 | E37: 25.08.2026 Sal | F37: 1.5 | G37: 5.3 | H37: B-01
A38: Faz 5 — Admin Auth (JWT) | B38: 5.5 | C38: Projects ve Posts'un tüm POST/PUT/PATCH/DELETE endpoint'lerini Depends(get_current_admin) ile koru | D38: 8 | E38: 25.08.2026 Sal | F38: 1 | G38: 5.4 | H38: B-01
A39: Faz 5 — Admin Auth (JWT) | B39: 5.6 | C39: scripts/create_admin.py — env'den admin oluşturur. Public register endpoint'i AÇMA | D39: 8 | E39: 25.08.2026 Sal | F39: 0.5 | G39: 5.2 | H39: B-01
A40: Faz 5 — Admin Auth (JWT) | B40: 5.7 | C40: test_auth.py: token'sız yazma→401, geçersiz/süresi dolmuş token→401, geçerli token→200 | D40: 8 | E40: 25.08.2026 Sal | F40: 1 | G40: 5.5 | H40: B-14
...

Sheet Özet
A1: Personal Portfolio Backend — İlerleme Özeti
A2: Plan tarihi: 18.08.2026 · Süre: 14 gün (18–31 Ağustos 2026)
A3: Görev Takibi sekmesindeki "Yapıldı mı?" sütununa ✓ girdikçe bu tablo kendini günceller.
A5: Faz | B5: Görev | C5: Biten | D5: Toplam efor (sa) | E5: Biten efor (sa) | F5: İlerleme
A6: Faz 0 — Temizlik ve Zemin | B6: =COUNTIF('Görev Takibi'!$A$2:$A$60,$A6) -> 9 | C6: =COUNTIFS('Görev Takibi'!$A$2:$A$60,$A6,'Görev Takibi'!$I$2:$I$60,"✓") -> 9 | D6: =SUMIF('Görev Takibi'!$A$2:$A$60,$A6,'Görev Takibi'!$F$2:$F$60) -> 3.83 | E6: =SUMIFS('Görev Takibi'!$F$2:$F$60,'Görev Takibi'!$A$2:$A$60,$A6,'Görev Takibi'!$I$2:$I$60,"✓") -> 3.83 | F6: =IFERROR($C6/$B6,0) -> 1
A7: Faz 1 — Router, Şema, Repository | B7: =COUNTIF('Görev Takibi'!$A$2:$A$60,$A7) -> 9 | C7: =COUNTIFS('Görev Takibi'!$A$2:$A$60,$A7,'Görev Takibi'!$I$2:$I$60,"✓") -> 9 | D7: =SUMIF('Görev Takibi'!$A$2:$A$60,$A7,'Görev Takibi'!$F$2:$F$60) -> 8.08 | E7: =SUMIFS('Görev Takibi'!$F$2:$F$60,'Görev Takibi'!$A$2:$A$60,$A7,'Görev Takibi'!$I$2:$I$60,"✓") -> 8.08 | F7: =IFERROR($C7/$B7,0) -> 1
A8: Faz 2 — Test Altyapısı | B8: =COUNTIF('Görev Takibi'!$A$2:$A$60,$A8) -> 3 | C8: =COUNTIFS('Görev Takibi'!$A$2:$A$60,$A8,'Görev Takibi'!$I$2:$I$60,"✓") -> 0 | D8: =SUMIF('Görev Takibi'!$A$2:$A$60,$A8,'Görev Takibi'!$F$2:$F$60) -> 4.25 | E8: =SUMIFS('Görev Takibi'!$F$2:$F$60,'Görev Takibi'!$A$2:$A$60,$A8,'Görev Takibi'!$I$2:$I$60,"✓") -> 0 | F8: =IFERROR($C8/$B8,0) -> 0
A9: Faz 3 — Alembic + PostgreSQL | B9: =COUNTIF('Görev Takibi'!$A$2:$A$60,$A9) -> 5 | C9: =COUNTIFS('Görev Takibi'!$A$2:$A$60,$A9,'Görev Takibi'!$I$2:$I$60,"✓") -> 0 | D9: =SUMIF('Görev Takibi'!$A$2:$A$60,$A9,'Görev Takibi'!$F$2:$F$60) -> 5.25 | E9: =SUMIFS('Görev Takibi'!$F$2:$F$60,'Görev Takibi'!$A$2:$A$60,$A9,'Görev Takibi'!$I$2:$I$60,"✓") -> 0 | F9: =IFERROR($C9/$B9,0) -> 0
A10: Faz 4 — Blog (Post) Modülü | B10: =COUNTIF('Görev Takibi'!$A$2:$A$60,$A10) -> 6 | C10: =COUNTIFS('Görev Takibi'!$A$2:$A$60,$A10,'Görev Takibi'!$I$2:$I$60,"✓") -> 0 | D10: =SUMIF('Görev Takibi'!$A$2:$A$60,$A10,'Görev Takibi'!$F$2:$F$60) -> 8.25 | E10: =SUMIFS('Görev Takibi'!$F$2:$F$60,'Görev Takibi'!$A$2:$A$60,$A10,'Görev Takibi'!$I$2:$I$60,"✓") -> 0 | F10: =IFERROR($C10/$B10,0) -> 0
A11: Faz 5 — Admin Auth (JWT) | B11: =COUNTIF('Görev Takibi'!$A$2:$A$60,$A11) -> 7 | C11: =COUNTIFS('Görev Takibi'!$A$2:$A$60,$A11,'Görev Takibi'!$I$2:$I$60,"✓") -> 0 | D11: =SUMIF('Görev Takibi'!$A$2:$A$60,$A11,'Görev Takibi'!$F$2:$F$60) -> 8.5 | E11: =SUMIFS('Görev Takibi'!$F$2:$F$60,'Görev Takibi'!$A$2:$A$60,$A11,'Görev Takibi'!$I$2:$I$60,"✓") -> 0 | F11: =IFERROR($C11/$B11,0) -> 0
A12: Faz 6 — Medya + İletişim | B12: =COUNTIF('Görev Takibi'!$A$2:$A$60,$A12) -> 7 | C12: =COUNTIFS('Görev Takibi'!$A$2:$A$60,$A12,'Görev Takibi'!$I$2:$I$60,"✓") -> 0 | D12: =SUMIF('Görev Takibi'!$A$2:$A$60,$A12,'Görev Takibi'!$F$2:$F$60) -> 8.75 | E12: =SUMIFS('Görev Takibi'!$F$2:$F$60,'Görev Takibi'!$A$2:$A$60,$A12,'Görev Takibi'!$I$2:$I$60,"✓") -> 0 | F12: =IFERROR($C12/$B12,0) -> 0
A13: Faz 7 — Docker + Droplet | B13: =COUNTIF('Görev Takibi'!$A$2:$A$60,$A13) -> 9 | C13: =COUNTIFS('Görev Takibi'!$A$2:$A$60,$A13,'Görev Takibi'!$I$2:$I$60,"✓") -> 0 | D13: =SUMIF('Görev Takibi'!$A$2:$A$60,$A13,'Görev Takibi'!$F$2:$F$60) -> 10.75 | E13: =SUMIFS('Görev Takibi'!$F$2:$F$60,'Görev Takibi'!$A$2:$A$60,$A13,'Görev Takibi'!$I$2:$I$60,"✓") -> 0 | F13: =IFERROR($C13/$B13,0) -> 0
A14: Faz 8 — Kapanış | B14: =COUNTIF('Görev Takibi'!$A$2:$A$60,$A14) -> 4 | C14: =COUNTIFS('Görev Takibi'!$A$2:$A$60,$A14,'Görev Takibi'!$I$2:$I$60,"✓") -> 0 | D14: =SUMIF('Görev Takibi'!$A$2:$A$60,$A14,'Görev Takibi'!$F$2:$F$60) -> 4 | E14: =SUMIFS('Görev Takibi'!$F$2:$F$60,'Görev Takibi'!$A$2:$A$60,$A14,'Görev Takibi'!$I$2:$I$60,"✓") -> 0 | F14: =IFERROR($C14/$B14,0) -> 0
A15: TOPLAM | B15: =SUM(B6:B14) -> 59 | C15: =SUM(C6:C14) -> 18 | D15: =SUM(D6:D14) -> 61.66 | E15: =SUM(E6:E14) -> 11.91 | F15: =IFERROR($C15/$B15,0) -> 0.30508475
A17: Kesme sırası (takvim sıkışırsa):
A18: 1) 6.6 e-posta bildirimi → 2) 8.1 GitHub Actions → 3) 7.8 yedekleme cron'u (manuel pg_dump mutlaka al)

Sheet Denetim Bulguları
A1: Kod | B1: Öncelik | C1: Dosya | D1: Bulgu | E1: Çözüldüğü görev | F1: Çözüldü mü?
A2: B-01 | B2: Blocker | C2: app/core/security.py, app/api/v1/projects.py | D2: Yazma endpoint'leri tamamen korumasız; security.py yorum satırı + debug print içeriyor; yorumdaki verify_password düz metin karşılaştırıyor | E2: 0.6, Faz 5
A3: B-02 | B3: Blocker | C3: requirements.txt | D3: aiosqltite yazım hatası → pip install çalışmıyor; pydantic-settings ve greenlet eksik; databases gereksiz; sürüm pinlenmemiş | E3: 0.3 | F3: ✓
A4: B-03 | B4: Blocker | C4: .gitignore | D4: myvenv/, dev.db, v1_db.db git takibinde; .gitignore sadece .env ve __pycache__ kapsıyor | E4: 0.1, 0.2
A5: B-04 | B5: Yüksek | C5: app/api/v1/projects.py, app/schemas/project.py | D5: POST body ProjectBase → id zorunlu (422) ve client primary key belirleyebiliyor (id=99 ile 200 döndü). ProjectCreate hiç kullanılmıyor ve slug içermiyor | E5: 1.2 | F5: ✓
A6: B-05 | B6: Yüksek | C6: app/api/v1/projects.py | D6: response_model olarak SQLModel table model kullanılıyor → ileride hashed_password gibi alanlar API'ye sızabilir | E6: 1.3
A7: B-06 | B7: Yüksek | C7: app/db.py | D7: Migration yok; create_all var olan tabloya kolon eklemez → yeni alan sessizce uygulanmaz | E7: 3.1, 3.2
A8: B-07 | B8: Yüksek | C8: app/api/v1/projects.py, app/repositories/base.py | D8: UPDATE/DELETE endpoint'i yok; update tüm alanları yazıyor → partial update imkânsız | E8: 1.6, 1.7 | F8: ✓
A9: B-08 | B9: Yüksek | C9: app/db.py | D9: db_dependency'de rollback/hata yönetimi yok | E9: 1.8
A10: B-09 | B10: Orta | C10: app/repositories/base.py | D10: get_by_slug base'e ait değil; self.model.slug slug'sız modellerde AttributeError | E10: 1.6
A11: B-10 | B11: Orta | C11: app/models/base.py | D11: BaseModel her modele name alanını zorunlu kılıyor — domain kararı değil, kolaylık kararı | E11: 1.5 | F11: ✓
A12: B-11 | B12: Orta | C12: app/models/base.py | D12: updated_at alanı yok — blogda 'son güncelleme' gerekecek | E12: 1.5 | F12: ✓
A13: B-12 | B13: Orta | C13: app/schemas/project.py | D13: liveDemo modelde var ama ProjectBase şemasında yok → API'den doldurulamıyor | E13: 1.2 | F13: ✓
A14: B-13 | B14: Orta | C14: dependencies/exceptions/middleware/router.py | D14: Boş (0 byte) stub dosyalar; router aggregation kullanılmıyor; logging.py tek satır | E14: 1.1, 7.4
A15: B-14 | B15: Orta | C15: tests/ | D15: Test yok, tests/ klasörü bile mevcut değil | E15: 2.1, 2.2, 5.7
A16: B-15 | B16: Orta | C16: app/main.py | D16: CORS origin'leri hardcoded localhost — droplet'te frontend çalışmaz | E16: 0.4, 7.7 | F16: ✓
A17: B-16 | B17: Orta | C17: app/models/project.py | D17: techStack/githubLink/liveDemo camelCase — PEP 8'e aykırı; alias_generator ile çözülmeli | E17: 1.4 | F17: ✓
A18: B-17 | B18: Düşük | C18: README.md | D18: UTF-16 kodlanmış, ağaç karakterleri bozuk; hâlâ users/orders örneğini anlatıyor | E18: 0.7 | F18: ✓
A19: B-18 | B19: Düşük | C19: — | D19: .env.example yok — projeyi başka makinede kurmak için hangi değişkenler gerektiği belirsiz | E19: 0.5 | F19: ✓
A20: B-19 | B20: Düşük | C20: app/api/__init__.py | D20: from .v1 import * — wildcard import | E20: 1.1 | F20: ✓
A21: B-20 | B21: Düşük | C21: app/models/readme.md, app/schemas/readme.md | D21: Var olmayan blog.py'yi anlatıyor | E21: 0.7 | F21: ✓
A22: B-21 | B22: Düşük | C22: app/repositories/base.py | D22: get_all limiti 1000 sabit; sayfalama metadata'sı (total/page) yok | E22: 1.7
A23: B-22 | B23: Düşük | C23: — | D23: Yerel Python 3.14 çok yeni; Docker imajında 3.12 gibi oturmuş sürüm tercih edilmeli | E23: 7.1
